<?xml version="1.0" ?>
<robot name="BAMBULAB_P2S" xmlns:xacro="http://www.ros.org/wiki/xacro">

<xacro:include filename="$(find BAMBULAB_P2S_description)/urdf/materials.xacro" />
<xacro:include filename="$(find BAMBULAB_P2S_description)/urdf/BAMBULAB_P2S.trans" />
<xacro:include filename="$(find BAMBULAB_P2S_description)/urdf/BAMBULAB_P2S.gazebo" />
<link name="base_link">
  <inertial>
    <origin xyz="0.21251632537877285 0.2681457970411163 0.30367863645273874" rpy="0 0 0"/>
    <mass value="144.76072983211262"/>
    <inertia ixx="6.607565" iyy="7.040119" izz="5.4012" ixy="-0.029571" iyz="0.186731" ixz="0.015142"/>
  </inertial>
  <visual>
    <origin xyz="0 0 0" rpy="0 0 0"/>
    <geometry>
      <mesh filename="package://BAMBULAB_P2S_description/meshes/base_link.stl" scale="0.001 0.001 0.001"/>
    </geometry>
    <material name="silver"/>
  </visual>
  <collision>
    <origin xyz="0 0 0" rpy="0 0 0"/>
    <geometry>
      <mesh filename="package://BAMBULAB_P2S_description/meshes/base_link.stl" scale="0.001 0.001 0.001"/>
    </geometry>
  </collision>
</link>

<link name="Z-bed_1">
  <inertial>
    <origin xyz="0.08596271129982927 0.0918236657916594 -0.05094513028013968" rpy="0 0 0"/>
    <mass value="10.019848039853946"/>
    <inertia ixx="0.064602" iyy="0.080198" izz="0.144424" ixy="-8.3e-05" iyz="0.0" ixz="0.0"/>
  </inertial>
  <visual>
    <origin xyz="-0.126543 -0.173367 -0.157117" rpy="0 0 0"/>
    <geometry>
      <mesh filename="package://BAMBULAB_P2S_description/meshes/Z-bed_1.stl" scale="0.001 0.001 0.001"/>
    </geometry>
    <material name="silver"/>
  </visual>
  <collision>
    <origin xyz="-0.126543 -0.173367 -0.157117" rpy="0 0 0"/>
    <geometry>
      <mesh filename="package://BAMBULAB_P2S_description/meshes/Z-bed_1.stl" scale="0.001 0.001 0.001"/>
    </geometry>
  </collision>
</link>

<link name="Y-axis_1">
  <inertial>
    <origin xyz="0.062419804737599976 -0.05776411722454011 -0.07414777976544817" rpy="0 0 0"/>
    <mass value="1.2845247547395635"/>
    <inertia ixx="0.000542" iyy="0.022739" izz="0.022652" ixy="0.0" iyz="-0.0" ixz="-0.0"/>
  </inertial>
  <visual>
    <origin xyz="-0.15016 -0.450867 -0.554722" rpy="0 0 0"/>
    <geometry>
      <mesh filename="package://BAMBULAB_P2S_description/meshes/Y-axis_1.stl" scale="0.001 0.001 0.001"/>
    </geometry>
    <material name="silver"/>
  </visual>
  <collision>
    <origin xyz="-0.15016 -0.450867 -0.554722" rpy="0 0 0"/>
    <geometry>
      <mesh filename="package://BAMBULAB_P2S_description/meshes/Y-axis_1.stl" scale="0.001 0.001 0.001"/>
    </geometry>
  </collision>
</link>

<link name="X-axis_nozzle_1">
  <inertial>
    <origin xyz="0.01995246450171534 -0.014186409462614735 -0.02101543607495132" rpy="0 0 0"/>
    <mass value="0.675060661578604"/>
    <inertia ixx="0.00026" iyy="0.000242" izz="0.000193" ixy="-0.0" iyz="-6e-06" ixz="-1e-06"/>
  </inertial>
  <visual>
    <origin xyz="-0.08758 -0.393103 -0.501277" rpy="0 0 0"/>
    <geometry>
      <mesh filename="package://BAMBULAB_P2S_description/meshes/X-axis_nozzle_1.stl" scale="0.001 0.001 0.001"/>
    </geometry>
    <material name="silver"/>
  </visual>
  <collision>
    <origin xyz="-0.08758 -0.393103 -0.501277" rpy="0 0 0"/>
    <geometry>
      <mesh filename="package://BAMBULAB_P2S_description/meshes/X-axis_nozzle_1.stl" scale="0.001 0.001 0.001"/>
    </geometry>
  </collision>
</link>

<link name="Door_1">
  <inertial>
    <origin xyz="0.03 -0.03 0" rpy="0 0 0"/>
    <mass value="1.8912702022608048"/>
    <inertia ixx="0.02213" iyy="0.03801" izz="0.015883" ixy="2.6e-05" iyz="3e-06" ixz="-8.5e-05"/>
  </inertial>
  <visual>
    <origin xyz="0.03 -0.03 0" rpy="0 0 0"/>
    <geometry>
      <mesh filename="package://BAMBULAB_P2S_description/meshes/Door_1.stl" scale="0.001 0.001 0.001"/>
    </geometry>
    <material name="silver"/>
  </visual>
  <collision>
    <origin xyz="0.03 -0.03 0" rpy="0 0 0"/>
    <geometry>
      <mesh filename="package://BAMBULAB_P2S_description/meshes/Door_1.stl" scale="0.001 0.001 0.001"/>
    </geometry>
  </collision>
</link>

<joint name="Z-axis" type="prismatic">
  <origin xyz="0.126543 0.173367 0.157117" rpy="0 0 0"/>
  <parent link="base_link"/>
  <child link="Z-bed_1"/>
  <axis xyz="-0.0 -0.0 -1.0"/>
  <limit upper="0.0" lower="-0.31" effort="100" velocity="100"/>
</joint>

<joint name="Y-axis" type="prismatic">
  <origin xyz="0.15016 0.450867 0.554722" rpy="0 0 0"/>
  <parent link="base_link"/>
  <child link="Y-axis_1"/>
  <axis xyz="0.0 1.0 0.0"/>
  <limit upper="0.0" lower="-0.25" effort="100" velocity="100"/>
</joint>

<joint name="X-axis" type="prismatic">
  <origin xyz="-0.06258 -0.057764 -0.053445" rpy="0 0 0"/>
  <parent link="Y-axis_1"/>
  <child link="X-axis_nozzle_1"/>
  <axis xyz="-1.0 0.0 -0.0"/>
  <limit upper="0.0" lower="-0.21" effort="100" velocity="100"/>
</joint>

<joint name="Revolute 8" type="revolute">
  <origin xyz="-0.03 0.03 0" rpy="0 0 0"/>
  <parent link="base_link"/>
  <child link="Door_1"/>
  <axis xyz="-0.0 -0.0 -1.0"/>
  <limit upper="3.141593" lower="0.0" effort="100" velocity="100"/>
</joint>

</robot>
